<?xml version="1.0"?>
<robot xmlns:xacro="http://www.ros.org/wiki/xacro" name="VLP-16">
  <xacro:property name="M_PI" value="3.1415926535897931" />
  <xacro:macro name="VLP-16" params="parent name topic *origin">

    <joint name="${name}_base_mount_joint" type="revolute">
      <xacro:insert_block name="origin" /> 
      <parent link="${parent}"/>
      <child link="${name}_offset_link"/>
      <limit effort="1000.0" lower="-1.0" upper="1.0" velocity="0.5"/>
      <axis xyz="0 1 0"/>
    </joint>

    <link name="${name}_offset_link">
      <inertial>
        <mass value="0.1"/>
        <origin xyz="0 0 0"/>
        <inertia ixx="0.1" ixy="0" ixz="0" iyy="0.1" iyz="0" izz="0.1"/>
      </inertial>
    </link>

    <joint name="${name}_base_offset_joint" type="fixed">
      <origin xyz="0 0 0.03" rpy="0 0 0" />
      <parent link="${name}_offset_link"/>
      <child link="${name}_base_link"/>
    </joint>

    <link name="${name}_base_link">
      <inertial>
        <mass value="0.1"/>
        <origin xyz="0 0 0"/>
        <inertia ixx="0.1" ixy="0" ixz="0" iyy="0.1" iyz="0" izz="0.1"/>
      </inertial>
      <visual>
        <geometry>
          <mesh filename="package://velodyne_description/meshes/VLP16_base_1.dae" />
        </geometry>
      </visual>
      <visual>
        <geometry>
          <mesh filename="package://velodyne_description/meshes/VLP16_base_2.dae" />
        </geometry>
      </visual>
      <collision name="${name}_base_link_collision">
        <origin rpy="0 0 0" xyz="0 0 0.03585"/>
        <geometry>
          <!-- <cylinder radius="0.0516" length="0.0717"/> -->
          <sphere radius="0.3"/>
        </geometry>
      </collision>
    </link>

    <joint name="${name}_base_scan_joint" type="fixed" >
      <origin xyz="0 0 0.0377" rpy="0 0 0" />
      <parent link="${name}_base_link" />
      <child link="${name}"/>
    </joint>
        
    <link name="${name}">
      <inertial>
        <mass value="0.1"/>
        <origin xyz="0 0 0"/>
        <inertia ixx="0.1" ixy="0" ixz="0" iyy="0.1" iyz="0" izz="0.1"/>
      </inertial>
      <visual>
        <origin xyz="0 0 -0.0377" />
        <geometry>
          <mesh filename="package://velodyne_description/meshes/VLP16_scan.dae" />
        </geometry>
      </visual>
    </link>

    <joint name="${name}_base_static_joint" type="fixed" >
      <origin xyz="0 0 0.0377" rpy="0 0 0" />
      <parent link="${parent}"/>
      <child link="${name}_static"/>
    </joint>

    <link name="${name}_static">
      <inertial>
        <mass value="0.1"/>
        <origin xyz="0 0 0"/>
        <inertia ixx="0.1" ixy="0" ixz="0" iyy="0.1" iyz="0" izz="0.1"/>
      </inertial>
    </link>

    <joint name="${name}_optical_joint" type="fixed" >
      <origin xyz="0 0 0" rpy="${-M_PI/2} 0 ${-M_PI/2}"/>
      <parent link="${name}_static"/>
      <child link="${name}_optical"/>
    </joint>

    <link name="${name}_optical">
      <inertial>
        <mass value="0.1"/>
        <origin xyz="0 0 0"/>
        <inertia ixx="0.1" ixy="0" ixz="0" iyy="0.1" iyz="0" izz="0.1"/>
      </inertial>
    </link>

    <!-- Gazebo requires the velodyne_gazebo_plugins package -->
    <gazebo reference="${name}">
      <sensor type="ray" name="${name}-VLP16">
        <pose>0 0 0 0 0 0</pose>
        <visualize>false</visualize>
        <update_rate>10</update_rate>
        <ray>
          <scan>
            <horizontal>
              <samples>900</samples>
              <resolution>1</resolution>
              <min_angle>-${M_PI}</min_angle>
              <max_angle> ${M_PI}</max_angle>
            </horizontal>
            <vertical>
              <samples>16</samples>
              <resolution>1</resolution>
              <min_angle>-${15.0*M_PI/180.0}</min_angle>
              <max_angle> ${15.0*M_PI/180.0}</max_angle>
            </vertical>
          </scan>
          <range>
            <min>0.31</min> 
            <!-- <min>0.055</min> -->
            <max>140.0</max>
            <resolution>0.001</resolution>
          </range>
          <noise>
            <type>gaussian</type>
            <mean>0.0</mean>
            <stddev>0.0</stddev>
          </noise>
        </ray>
        <plugin name="gazebo_ros_laser_controller" filename="libgazebo_ros_velodyne_laser.so">
          <topicName>${topic}</topicName>
          <frameName>/${name}</frameName>
          <min_range>0.5</min_range>
          <max_range>100.0</max_range>
          <gaussianNoise>0.008</gaussianNoise>
        </plugin>
      </sensor>
    </gazebo>

    <gazebo reference="${name}_base_link">
      <sensor name="velodyne_contact" type='contact'>
        <always_on>true</always_on>
        <update_rate>5</update_rate>
        <contact>
          <collision>${name}_base_link_collision</collision>
        </contact>
      </sensor>
    </gazebo>

  <gazebo>
    <plugin name="pose_controller" filename="libgazebo_ros_pose_controller.so">
        <joint_name> ${name}_base_mount_joint </joint_name>
        <contact_sensor_name> velodyne_contact </contact_sensor_name>
        <velodyne_sensor_name> ${name}-VLP16 </velodyne_sensor_name>
        <speed>0.5</speed>
    </plugin>
  </gazebo>
  </xacro:macro>
</robot>
